<?xml version="1.0" ?>

<sdf version='1.6'>
<model name='aidin8'>
<static>false</static>
<pose>0 0 1 0 0 0</pose>

<link name='body'>
      <pose>0 0 0 0 0 0</pose>
      <inertial>
        <mass>4.5711</mass>
        <pose>0 0 0 0 0 0</pose>
        <inertia>
          <ixx>0.0795</ixx>
          <ixy>0</ixy>
          <ixz>0</ixz>
          <iyy>0.4503</iyy>
          <iyz>0</iyz>
          <izz>0.4845</izz>
        </inertia>
      </inertial>

      <visual name="body_visual">
	<pose>0 0 0 0 0 0</pose>
        <material>
          <ambient>0.752941176470588 0.752941176470588 0.752941176470588 1</ambient>
          <diffuse>0.752941176470588 0.752941176470588 0.752941176470588 1</diffuse>
        </material>
        <geometry>
          <mesh>
            <scale>1 1 1</scale>
            <uri>model://aidin8/meshes/meshes_surface/Body.STL</uri>
          </mesh>
        </geometry>
        <material name="black"/>
      </visual>

      <collision name='body_1'>
        <pose>0.4294 0 0 0 0 0</pose>
        <geometry>
    	  <box>
            <size>0.026 0.318 0.207</size>
          </box>
        </geometry>
	<surface>
            <friction>
              <ode>
                <mu>100.000000</mu>
                <mu2>100.000000</mu2>
              </ode>
            </friction>
          </surface>
      </collision>

      <collision name='body_2'>
        <pose>-0.4294 0 0 0 0 0</pose>
        <geometry>
    	  <box>
            <size>0.026 0.318 0.207</size>
          </box>
        </geometry>
	<surface>
            <friction>
              <ode>
                <mu>100.000000</mu>
                <mu2>100.000000</mu2>
              </ode>
            </friction>
          </surface>
      </collision>

      <collision name='body_3'>
        <pose>0 0.119 0.085 0 1.57079632679 0</pose>
        <geometry>
        <cylinder>
            <length>0.8848</length>
            <radius>0.0102</radius>
          </cylinder>
        </geometry>
	<surface>
            <friction>
              <ode> 
                <mu>100.000000</mu>
                <mu2>100.000000</mu2>
              </ode>
            </friction>
          </surface>
      </collision>

      <collision name='body_4'>
        <pose>0 0.119 -0.085 0 1.57079632679 0</pose>
        <geometry>
        <cylinder>
            <length>0.8848</length>
            <radius>0.0102</radius>
          </cylinder>
        </geometry>
	<surface>
            <friction>
              <ode> 
                <mu>100.000000</mu>
                <mu2>100.000000</mu2>
              </ode>
            </friction>
          </surface>
      </collision>

      <collision name='body_5'>
        <pose>0 -0.119 0.085 0 1.57079632679 0</pose>
        <geometry>
        <cylinder>
            <length>0.8848</length>
            <radius>0.0102</radius>
          </cylinder>
        </geometry>
	<surface>
            <friction>
              <ode> 
                <mu>100.000000</mu>
                <mu2>100.000000</mu2>
              </ode>
            </friction>
          </surface>
      </collision>

      <collision name='body_6'>
        <pose>0 -0.119 -0.085 0 1.57079632679 0</pose>
        <geometry>
        <cylinder>
            <length>0.8848</length>
            <radius>0.0102</radius>
          </cylinder>
        </geometry>
	<surface>
            <friction>
              <ode> 
                <mu>100.000000</mu>
                <mu2>100.000000</mu2>
              </ode>
            </friction>
          </surface>
      </collision>
</link>

  <link name='LF_1'> <!--front left shoulder -->
     <pose>+0.3374 +0.119 0 1.57079632679 0 1.57079632679</pose>
     <inertial>
        <mass>6.0096951</mass>
        <pose>0.0023715 -0.000018 -0.0357731 0 0 0</pose>
        <inertia>
          <ixx>0.0255651507491</ixx>
          <ixy>0.000015354212</ixy>
          <ixz>0.0009948486793</ixz>
          <iyy>0.0359354752104</iyy>
          <iyz>0.0000144486745</iyz>
          <izz>0.0169032756867</izz>
        </inertia>
      </inertial>

      <visual name="LF_vis11">
        <pose>0 0 0 0 0 0</pose>
        <material>
          <ambient>0.752941176470588 0.752941176470588 0.752941176470588 1</ambient>
          <diffuse>0.752941176470588 0.752941176470588 0.752941176470588 1</diffuse>
        </material>
        <geometry>
          <mesh>
            <scale>1 1 1</scale>
            <uri>model://aidin8/meshes/meshes_surface/Leg_Scapular_LF_stp_v2.STL</uri>
          </mesh>
        </geometry>
        <material name="black"/>
      </visual>

      <collision name='LF_col1'>
        <pose>0 0 -0.0507 0 0 0</pose>
        <geometry>
        <cylinder>
            <length>0.2334</length>
            <radius>0.0535</radius>
          </cylinder>
        </geometry>
	<surface>
            <friction>
              <ode>
                <mu>100.000000</mu>
                <mu2>100.000000</mu2>
              </ode>
            </friction>
          </surface>
      </collision>

      <collision name='LF_col2'>
        <pose>0.0083 0 0 0 1.57079632679 0</pose>
        <geometry>
        <cylinder>
            <length>0.1984</length>
            <!--length>0.19</length-->
            <radius>0.0535</radius>
          </cylinder>
        </geometry>
	<surface>
            <friction>
              <ode>
                <mu>100.000000</mu>
                <mu2>100.000000</mu2>
              </ode>
            </friction>
          </surface>
      </collision>
</link>

<link name='LF_2'> <!-- front left leg upper-->
      <pose>+0.3374 +0.2535 0 1.57079632679 1.57079632679 0</pose>
      <inertial>
        <mass>0.8320777</mass>
        <pose>0.1763086 -0.0152343 -0.0002264 0 0 0</pose>
        <inertia>
          <ixx>0.0007072507423</ixx>
          <ixy>0.0000163954475</ixy>
          <ixz>0.0000331849652</ixz>
          <iyy>0.015000924209</iyy>
          <iyz>-0.0000028381293</iyz>
          <izz>0.0149901916315</izz>
        </inertia>
      </inertial>

      <visual name="LF2_vis11">
        <pose>0 0 0 0 0 0</pose>
        <material>
          <ambient>1 0 0 1</ambient>
          <diffuse>1 0 0 1</diffuse>
        </material>
        <geometry>
          <mesh>
            <scale>1 1 1</scale>
            <uri>model://aidin8/meshes/meshes_surface/Leg_Hip_left_stp.STL</uri>
          </mesh>
        </geometry>
        <material name="red"/>
      </visual>

      <collision name='LF2_col1'>
        <pose>0 0 0 0 0 0</pose>
        <geometry>
        <cylinder>
            <length>0.054</length>
            <radius>0.027</radius>
          </cylinder>
        </geometry>
	<surface>
            <friction>
              <ode>
                <mu>100.000000</mu>
                <mu2>100.000000</mu2>
              </ode>
            </friction>
          </surface>
      </collision>

      <collision name='LF2_col2'>
        <pose>0.055 -0.021 0 0 0 0</pose>
        <geometry>
    	  <box>
              <size>0.06 0.06 0.054</size>
          </box>
        </geometry>
	<surface>
            <friction>
              <ode>
                <mu>100.000000</mu>
                <mu2>100.000000</mu2>
              </ode>
            </friction>
          </surface>
      </collision>

      <collision name='LF2_col3'>
        <pose>0.175 -0.021 0 0 1.57079632679 0</pose>
        <geometry>
        <cylinder>
            <length>0.18</length>
            <radius>0.025</radius>
          </cylinder>
        </geometry>
	<surface>
            <friction>
              <ode>
                <mu>100.000000</mu>
                <mu2>100.000000</mu2>
              </ode>
            </friction>
          </surface>
      </collision>

      <collision name='LF2_col4'>
         <pose>0.295 -0.021 0 0 0 0</pose>
        <geometry>
    	  <box>
              <size>0.06 0.06 0.054</size>
          </box>
        </geometry>
	<surface>
            <friction>
              <ode>
                <mu>100.000000</mu>
                <mu2>100.000000</mu2>
              </ode>
            </friction>
          </surface>
      </collision>

      <collision name='LF2_col5'>
        <pose>0.35 0 0.0245 0 0 0</pose>
        <geometry>
        <cylinder>
            <length>0.011 </length>
            <radius>0.027</radius>
          </cylinder>
        </geometry>
	<surface>
            <friction>
              <ode>
                <mu>100.000000</mu>
                <mu2>100.000000</mu2>
              </ode>
            </friction>
          </surface>
      </collision>

      <collision name='LF2_col6'>
        <pose>0.35 0 -0.0245 0 0 0</pose>
        <geometry>
        <cylinder>
            <length>0.011 </length>
            <radius>0.027</radius>
          </cylinder>
        </geometry>
	<surface>
            <friction>
              <ode>
                <mu>100.000000</mu>
                <mu2>100.000000</mu2>
              </ode>
            </friction>
          </surface>
      </collision>

      <!--collision name='LF2_col8'--> <!-- joint position-->
<!--
        <pose>-0.0175 0 -0.35 1.57079632679 1.57079632679 1.57079632679</pose>
        <geometry>
        <cylinder>
            <length>0.01</length>
            <radius>0.0225</radius>
          </cylinder>
        </geometry>
	<surface>
            <friction>
              <ode>
                <mu>100.000000</mu>
                <mu2>100.000000</mu2>
              </ode>
            </friction>
          </surface>
      </collision>
-->
</link>

<link name='LF_3'> <!-- front left lower leg -->
      <pose>+0.3374 +0.2535 -0.35 1.57079632679 1.57079632679 0</pose>
      <inertial>
        <mass>0.5761362</mass>
        <pose>0.12407 0.019161 0 0 0 0</pose>
        <inertia>
          <ixx>0.0005064730114</ixx>
          <ixy>0.0011799485469</ixy>
          <ixz>0</ixz>
          <iyy>0.0112618365401</iyy>
          <iyz>0</iyz>
          <izz>0.0115659868838</izz>
        </inertia>
      </inertial>

      <visual name="LF3_vis11">
        <pose>0 0 0 0 0 0</pose>
        <material>
          <ambient>0.196078431372549 0.196078431372549 0.196078431372549 1</ambient>
          <diffuse>0.196078431372549 0.196078431372549 0.196078431372549 1</diffuse>
        </material>
        <geometry>
          <mesh>
            <scale>1 1 1</scale>
            <uri>model://aidin8/meshes/meshes_surface/Leg_Knee_stp.STL</uri>
          </mesh>
        </geometry>
      </visual>

      <collision name='LF3_col1'>
        <pose>0 0 0 0 0 0</pose>
        <geometry>
        <cylinder>
            <length>0.03</length>
            <radius>0.02</radius>
          </cylinder>
        </geometry>
	<surface>
            <friction>
              <ode>
                <mu>100.000000</mu>
                <mu2>100.000000</mu2>
              </ode>
            </friction>
          </surface>
      </collision>
<!--
      <collision name='LF3_col2'>
        <pose>0.0152 -0.0025 0 0 0 0</pose>
        <geometry>
    	  <box>
              <size>0.03 0.045 0.036</size>
          </box>
        </geometry>
	<surface>
            <friction>
              <ode>
                <mu>100.000000</mu>
                <mu2>100.000000</mu2>
              </ode>
            </friction>
          </surface>
      </collision>
-->
      <collision name='LF3_col3'>
        <pose>0.1007581 0.0255584 0 0 0 0.41887902048</pose>
        <geometry>
    	  <box>
              <size>0.17 0.035 0.036</size>
          </box>
        </geometry>
	<surface>
            <friction>
              <ode>
                <mu>100.000000</mu>
                <mu2>100.000000</mu2>
              </ode>
            </friction>
          </surface>
      </collision>

      <collision name='LF3_col4'>
        <pose>0.2109143 0.0609071 0 0 0 0.05925392811</pose>
        <geometry>
    	  <box>
              <size>0.0771692 0.035 0.036</size>
          </box>
        </geometry>
	<surface>
            <friction>
              <ode>
                <mu>100.000000</mu>
                <mu2>100.000000</mu2>
              </ode>
            </friction>
          </surface>
      </collision>
            
      <collision name='LF3_col5'>
        <pose>0.3223493 0.0351797 0 0 0 -0.34906585040</pose>
        <geometry>
    	  <box>
              <size>0.17 0.035 0.036</size>
          </box>
        </geometry>
	      <surface>
            <friction>
              <ode>
                <mu>100.000000</mu>
                <mu2>100.000000</mu2>
              </ode>
            </friction>
          </surface>
      </collision>

<!--front left foot sphere-->
      <!--collision name='LF3_col6'> 
      <max_contacts>10</max_contacts>
        <pose>0.4 0 0 0 0 0</pose>
        <geometry>
    	  <sphere>
              <radius>0.024</radius>
          </sphere>
        </geometry>
	      <surface>
            <friction>
              <ode>
                <mu>1000.000000</mu>
                <mu2>1000.000000</mu2>
              </ode>
            </friction>
          </surface>
      </collision-->

<!--front left foot cylinder-->
      <collision name='LF3_col7'>
      <max_contacts>10</max_contacts>
        <pose>0.4 0 0 0 0 0</pose>
        <geometry>
        <cylinder>
            <length>0.036</length>
            <radius>0.024</radius>
          </cylinder>
        </geometry>
	      <surface>
            <friction>
              <ode>
                <mu>1000.000000</mu>
                <mu2>1000.000000</mu2>
              </ode>
            </friction>
          </surface>
      </collision>

    <sensor name="LF_3_sensor" type="contact">
      <plugin name="LF_plugin" filename="libcontact.so"/>
      <always_on>true</always_on>
      <update_rate>250</update_rate>
      <contact>
        <collision>LF3_col6</collision>
      </contact>
    </sensor>
</link>

<link name='LF_link1'>
      <pose>+0.3374 +0.2535 0 1.57079632679 -1.74532925199 0</pose> <!-- 10도 -->
      <inertial>
        <mass>0.3184983</mass>
        <pose>0.008126 -0.0005283 0.0305419 0 0 0</pose>
        <inertia>
          <ixx>0.0007804785859</ixx>
          <ixy>0.00000226856</ixy>
          <ixz>-0.0000785325361</ixz>
          <iyy>0.0008456468004</iyy>
          <iyz>0.0000052002314</iyz>
          <izz>0.0001116486791</izz>
        </inertia>
      </inertial>

      <visual name="LF_link1_vis1">
        <pose>0 0 0 0 0 0</pose>
        <material>
          <ambient>0.196078431372549 0.196078431372549 0.196078431372549 1</ambient>
          <diffuse>0.196078431372549 0.196078431372549 0.196078431372549 1</diffuse>
        </material>
        <geometry>
          <mesh>
            <scale>1 1 1</scale>
            <uri>model://aidin8/meshes/meshes_surface/Knee_link1_left_stp.STL</uri>
          </mesh>
        </geometry>
      </visual>
</link>

<link name='LF_link2'>
      <pose>+0.3313223 +0.2535 +0.0344683 1.57079632679 1.57079632679 0</pose>
      <inertial>
        <mass>0.20931</mass>
        <pose>0.175 0 0 0 0 0</pose>
        <inertia>
          <ixx>0.00000747991</ixx>
          <ixy>0</ixy>
          <ixz>0</ixz>
          <iyy>0.00238918720</iyy>
          <iyz>0</iyz>
          <izz>0.00239407889</izz>
        </inertia>
      </inertial>

      <visual name="LF_link2_vis1">
        <pose>0 0 0 0 0 0</pose>
        <material>
          <ambient>0.752941176470588 0.752941176470588 0.752941176470588 1</ambient>
          <diffuse>0.752941176470588 0.752941176470588 0.752941176470588 1</diffuse>
        </material>
        <geometry>
          <mesh>
            <scale>1 1 1</scale>
            <uri>model://aidin8/meshes/meshes_surface/Knee_link2_stp.STL</uri>
          </mesh>
        </geometry>
      </visual>
</link>


  <link name='RF_1'> <!-- front right shoulder -->
      <pose>+0.3374 -0.119 0 -1.57079632679 0 -1.57079632679</pose>
      <inertial>
        <mass>6.0096951</mass>
        <pose>0.002369 -0.0000223 -0.0358104 0 0 0</pose>
        <inertia>
          <ixx>0.0255491010927</ixx>
          <ixy>0.0000047311707</ixy>
          <ixz>0.0009887851004</ixz>
          <iyy>0.0359194975559</iyy>
          <iyz>0.000008004696</iyz>
          <izz>0.016903345595</izz>
        </inertia>
      </inertial>

      <visual name="RF_vis1">
        <pose>0 0 0 0 0 0</pose>
        <material>
          <ambient>0.752941176470588 0.752941176470588 0.752941176470588 1</ambient>
          <diffuse>0.752941176470588 0.752941176470588 0.752941176470588 1</diffuse>
        </material>
        <geometry>
          <mesh>
            <scale>1 1 1</scale>
            <uri>model://aidin8/meshes/meshes_surface/Leg_Scapular_RF_stp_v2.STL</uri>
          </mesh>
        </geometry>
      </visual>

      <collision name='RF_col1'>
        <pose>0 0 -0.0507 0 0 0</pose>
        <geometry>
        <cylinder>
            <length>0.2334</length>
            <radius>0.0535</radius>
          </cylinder>
        </geometry>
	<surface>
            <friction>
              <ode>
                <mu>100.000000</mu>
                <mu2>100.000000</mu2>
              </ode>
            </friction>
          </surface>
      </collision>

      <collision name='RF_col2'>
        <pose>0.0083 0 0 0 1.57079632679 0</pose>
        <geometry>
        <cylinder>
            <length>0.1984</length>
            <radius>0.0535</radius>
          </cylinder>
        </geometry>
	<surface>
            <friction>
              <ode>
                <mu>100.000000</mu>
                <mu2>100.000000</mu2>
              </ode>
            </friction>
          </surface>
      </collision>
</link>

<link name='RF_2'> <!-- front right leg upper -->
      <pose>+0.3374 -0.2535 0 1.57079632679 1.57079632679 0</pose>
      <inertial>
        <mass>0.8320777</mass>
        <pose>0.1763086 -0.0152343 0.0002264 0 0 0</pose>
        <inertia>
          <ixx>0.0007072507437</ixx>
          <ixy>0.0000163954475</ixy>
          <ixz>-0.0000331847918</ixz>
          <iyy>0.0150009242104</iyy>
          <iyz>0.0000028380628</iyz>
          <izz>0.0149901916315</izz>
        </inertia>
      </inertial>

      <visual name="RF2_vis1">
        <pose>0 0 0 0 0 0</pose>
        <material>
          <ambient>1 0 0 1</ambient>
          <diffuse>1 0 0 1</diffuse>
        </material>
        <geometry>
          <mesh>
            <scale>1 1 1</scale>
            <uri>model://aidin8/meshes/meshes_surface/Leg_Hip_right_stp.STL</uri>
          </mesh>
        </geometry>
      </visual>

      <!-- <collision name='RF2_col1'>
        <pose>0.175 0 0 0 1.57079632679 0</pose>
        <geometry>
        <cylinder>
            <length>0.175</length>
            <radius>0.01</radius>
          </cylinder>
        </geometry>
	<surface>
            <friction>
              <ode>
                <mu>100.000000</mu>
                <mu2>100.000000</mu2>
              </ode>
            </friction>
          </surface>
      </collision> -->

      <!-- <collision name='RF2_col2'>
        <pose>0.055 -0.021 0 0 0 0</pose>
        <geometry>
    	  <box>
              <size>0.06 0.06 0.054</size>
          </box>
        </geometry>
	<surface>
            <friction>
              <ode>
                <mu>100.000000</mu>
                <mu2>100.000000</mu2>
              </ode>
            </friction>
          </surface>
      </collision>

      <collision name='RF2_col3'>
        <pose>0.175 -0.021 0 0 1.57079632679 0</pose>
        <geometry>
        <cylinder>
            <length>0.18</length>
            <radius>0.025</radius>
          </cylinder>
        </geometry>
	<surface>
            <friction>
              <ode>
                <mu>100.000000</mu>
                <mu2>100.000000</mu2>
              </ode>
            </friction>
          </surface>
      </collision>

      <collision name='RF2_col4'>
         <pose>0.295 -0.021 0 0 0 0</pose>
        <geometry>
    	  <box>
              <size>0.06 0.06 0.054</size>
          </box>
        </geometry>
	<surface>
            <friction>
              <ode>
                <mu>100.000000</mu>
                <mu2>100.000000</mu2>
              </ode>
            </friction>
          </surface>
      </collision>

      <collision name='RF2_col5'>
        <pose>0.35 0 0.0245 0 0 0</pose>
        <geometry>
        <cylinder>
            <length>0.011 </length>
            <radius>0.027</radius>
          </cylinder>
        </geometry>
	<surface>
            <friction>
              <ode>
                <mu>100.000000</mu>
                <mu2>100.000000</mu2>
              </ode>
            </friction>
          </surface>
      </collision>

      <collision name='RF2_col6'>
        <pose>0.35 0 -0.0245 0 0 0</pose>
        <geometry>
        <cylinder>
            <length>0.011 </length>
            <radius>0.027</radius>
          </cylinder>
        </geometry>
	<surface>
            <friction>
              <ode>
                <mu>100.000000</mu>
                <mu2>100.000000</mu2>
              </ode>
            </friction>
          </surface>
      </collision> -->


</link>

<link name='RF_3'> <!-- front right lower leg -->
      <pose>+0.3374 -0.2535 -0.35 1.57079632679 1.57079632679 0</pose>
      <inertial>
        <mass>0.5761362</mass>
        <pose>0.12407 0.019161 0 0 0 0</pose>
        <inertia>
          <ixx>0.0005064730114</ixx>
          <ixy>0.0011799485469</ixy>
          <ixz>0</ixz>
          <iyy>0.0112618365401</iyy>
          <iyz>0</iyz>
          <izz>0.0115659868838</izz>
        </inertia>
      </inertial>

      <visual name="RF3_vis11">
        <pose>0 0 0 0 0 0</pose>
        <material>
          <ambient>0.196078431372549 0.196078431372549 0.196078431372549 1</ambient>
          <diffuse>0.196078431372549 0.196078431372549 0.196078431372549 1</diffuse>
        </material>
        <geometry>
          <mesh>
            <scale>1 1 1</scale>
            <uri>model://aidin8/meshes/meshes_surface/Leg_Knee_stp.STL</uri>
          </mesh>
        </geometry>
      </visual>

      <collision name='RF3_col1'>
        <pose>0 0 0 0 0 0</pose>
        <geometry>
        <cylinder>
            <length>0.03</length>
            <radius>0.02</radius>
          </cylinder>
        </geometry>
	<surface>
            <friction>
              <ode>
                <mu>100.000000</mu>
                <mu2>100.000000</mu2>
              </ode>
            </friction>
          </surface>
      </collision>
<!--
      <collision name='RF3_col2'>
        <pose>0.0152 -0.0025 0 0 0 0</pose>
        <geometry>
    	  <box>
              <size>0.03 0.045 0.036</size>
          </box>
        </geometry>
	<surface>
            <friction>
              <ode>
                <mu>100.000000</mu>
                <mu2>100.000000</mu2>
              </ode>
            </friction>
          </surface>
      </collision>
-->
      <collision name='RF3_col3'>
        <pose>0.1007581 0.0255584 0 0 0 0.41887902048</pose>
        <geometry>
    	  <box>
              <size>0.17 0.035 0.036</size>
          </box>
        </geometry>
	<surface>
            <friction>
              <ode>
                <mu>100.000000</mu>
                <mu2>100.000000</mu2>
              </ode>
            </friction>
          </surface>
      </collision>

      <collision name='RF3_col4'>
        <pose>0.2109143 0.0609071 0 0 0 0.05925392811</pose>
        <geometry>
    	  <box>
              <size>0.0771692 0.035 0.036</size>
          </box>
        </geometry>
	<surface>
            <friction>
              <ode>
                <mu>100.000000</mu>
                <mu2>100.000000</mu2>
              </ode>
            </friction>
          </surface>
      </collision>
            
      <collision name='RF3_col5'>
        <pose>0.3223493 0.0351797 0 0 0 -0.34906585040</pose>
        <geometry>
    	  <box>
              <size>0.17 0.035 0.036</size>
          </box>
        </geometry>
	      <surface>
            <friction>
              <ode>
                <mu>100.000000</mu>
                <mu2>100.000000</mu2>
              </ode>
            </friction>
          </surface>
      </collision>

<!--front right foot sphere-->
      <!--collision name='RF3_col6'>
      <max_contacts>10</max_contacts>
        <pose>0.4 0 0 0 0 0</pose>
        <geometry>
    	  <sphere>
              <radius>0.024</radius>
          </sphere>
        </geometry>
	      <surface>
            <friction>
              <ode>
                <mu>1000.000000</mu>
                <mu2>1000.000000</mu2>
              </ode>
            </friction>
          </surface>
      </collision-->

<!--front right foot cylinder-->
      <collision name='RF3_col7'>
      <max_contacts>10</max_contacts>
        <pose>0.4 0 0 0 0 0</pose>
        <geometry>
        <cylinder>
            <length>0.036</length>
            <radius>0.024</radius>
          </cylinder>
        </geometry>
	      <surface>
            <friction>
              <ode>
                <mu>1000.000000</mu>
                <mu2>1000.000000</mu2>
              </ode>
            </friction>
          </surface>
      </collision>

    <sensor name="RF_3_sensor" type="contact">
      <plugin name="RF_plugin" filename="libcontact.so"/>
      <always_on>true</always_on>
      <update_rate>250</update_rate>
      <contact>
        <collision>RF3_col6</collision>
      </contact>
    </sensor>
</link>

<link name='RF_link1'>
      <pose>+0.3374 -0.2535 0 1.57079632679 -1.74532925199 0</pose> <!-- 10도 -->
      <inertial>
        <mass>0.3184983</mass>
        <pose>0.008126 -0.0005283 -0.0305419 0 0 0</pose>
        <inertia>
          <ixx>0.0007804785859</ixx>
          <ixy>0.00000226856</ixy>
          <ixz>0.0000785325361</ixz>
          <iyy>0.0008456468004</iyy>
          <iyz>-0.0000052002314</iyz>
          <izz>0.0001116486791</izz>
        </inertia>
      </inertial>
      <visual name="RF_link1_vis1">
        <pose>0 0 0 0 0 0</pose>
        <material>
          <ambient>0.196078431372549 0.196078431372549 0.196078431372549 1</ambient>
          <diffuse>0.196078431372549 0.196078431372549 0.196078431372549 1</diffuse>
        </material>
        <geometry>
          <mesh>
            <scale>1 1 1</scale>
            <uri>model://aidin8/meshes/meshes_surface/Knee_link1_right_stp.STL</uri>
          </mesh>
        </geometry>
      </visual>
</link>

<link name='RF_link2'>
      <pose>+0.3313223 -0.2535 +0.0344683 1.57079632679 1.57079632679 0</pose>
      <inertial>
        <mass>0.20931</mass>
        <pose>0.175 0 0 0 0 0</pose>
        <inertia>
          <ixx>0.00000747991</ixx>
          <ixy>0</ixy>
          <ixz>0</ixz>
          <iyy>0.00238918720</iyy>
          <iyz>0</iyz>
          <izz>0.00239407889</izz>
        </inertia>
      </inertial>
      <visual name="RF_link2_vis1">
        <pose>0 0 0 0 0 0</pose>
        <material>
          <ambient>0.752941176470588 0.752941176470588 0.752941176470588 1</ambient>
          <diffuse>0.752941176470588 0.752941176470588 0.752941176470588 1</diffuse>
        </material>
        <geometry>
          <mesh>
            <scale>1 1 1</scale>
            <uri>model://aidin8/meshes/meshes_surface/Knee_link2_stp.STL</uri>
          </mesh>
        </geometry>
      </visual>
</link>


  <link name='RB_1'> <!-- back right shoulder -->
      <pose>-0.3374 -0.119 0 -1.57079632679 0 -1.57079632679</pose>
      <inertial>
        <mass>6.0096951</mass>
        <pose>0.0023715 0.000018 0.0357731 0 0 0</pose>
        <inertia>
          <ixx>0.0255651507491</ixx>
          <ixy>-0.000015354212</ixy>
          <ixz>-0.0009948486793</ixz>
          <iyy>0.0359354752104</iyy>
          <iyz>0.0000144486745</iyz>
          <izz>0.0169032756867</izz>
        </inertia>
      </inertial>

      <visual name="RB_vis11">
        <pose>0 0 0 0 0 0</pose>
        <material>
          <ambient>0.752941176470588 0.752941176470588 0.752941176470588 1</ambient>
          <diffuse>0.752941176470588 0.752941176470588 0.752941176470588 1</diffuse>
        </material>
        <geometry>
          <mesh>
            <scale>1 1 1</scale>
            <uri>model://aidin8/meshes/meshes_surface/Leg_Scapular_RR_stp_v2.STL</uri>
          </mesh>
        </geometry>
      </visual>

      <collision name='RB_col1'>
        <pose>0 0 0.0507 0 0 0</pose>
        <geometry>
        <cylinder>
            <length>0.2334</length>
            <radius>0.0535</radius>
          </cylinder>
        </geometry>
	<surface>
            <friction>
              <ode>
                <mu>100.000000</mu>
                <mu2>100.000000</mu2>
              </ode>
            </friction>
          </surface>
      </collision>

      <collision name='RB_col2'>
        <pose>0.0083 0 0 0 1.57079632679 0</pose>
        <geometry>
        <cylinder>
            <length>0.1984</length>
            <radius>0.0535</radius>
          </cylinder>
        </geometry>
	<surface>
            <friction>
              <ode>
                <mu>100.000000</mu>
                <mu2>100.000000</mu2>
              </ode>
            </friction>
          </surface>
      </collision>
</link>

<link name='RB_2'> <!-- back right leg upper -->
      <pose>-0.3374 -0.2535 0 1.57079632679 1.57079632679 0</pose>
      <inertial>
        <mass>0.8320777</mass>
        <pose>0.1763086 -0.0152343 0.0002264 0 0 0</pose>
        <inertia>
          <ixx>0.0007072507437</ixx>
          <ixy>0.0000163954475</ixy>
          <ixz>-0.0000331847918</ixz>
          <iyy>0.0150009242104</iyy>
          <iyz>0.0000028380628</iyz>
          <izz>0.0149901916315</izz>
        </inertia>
      </inertial>

      <visual name="RB2_vis1">
        <pose>0 0 0 0 0 0</pose>
        <material>
          <ambient>1 0 0 1</ambient>
          <diffuse>1 0 0 1</diffuse>
        </material>
        <geometry>
          <mesh>
            <scale>1 1 1</scale>
            <uri>model://aidin8/meshes/meshes_surface/Leg_Hip_right_stp.STL</uri>
          </mesh>
        </geometry>
      </visual>

      <collision name='RB2_col1'>
        <pose>0 0 0 0 0 0</pose>
        <geometry>
        <cylinder>
            <length>0.054</length>
            <radius>0.027</radius>
          </cylinder>
        </geometry>
	<surface>
            <friction>
              <ode>
                <mu>100.000000</mu>
                <mu2>100.000000</mu2>
              </ode>
            </friction>
          </surface>
      </collision>

      <collision name='RB2_col2'>
        <pose>0.055 -0.021 0 0 0 0</pose>
        <geometry>
    	  <box>
              <size>0.06 0.06 0.054</size>
          </box>
        </geometry>
	<surface>
            <friction>
              <ode>
                <mu>100.000000</mu>
                <mu2>100.000000</mu2>
              </ode>
            </friction>
          </surface>
      </collision>

      <collision name='RB2_col3'>
        <pose>0.175 -0.021 0 0 1.57079632679 0</pose>
        <geometry>
        <cylinder>
            <length>0.18</length>
            <radius>0.025</radius>
          </cylinder>
        </geometry>
	<surface>
            <friction>
              <ode>
                <mu>100.000000</mu>
                <mu2>100.000000</mu2>
              </ode>
            </friction>
          </surface>
      </collision>

      <collision name='RB2_col4'>
         <pose>0.295 -0.021 0 0 0 0</pose>
        <geometry>
    	  <box>
              <size>0.06 0.06 0.054</size>
          </box>
        </geometry>
	<surface>
            <friction>
              <ode>
                <mu>100.000000</mu>
                <mu2>100.000000</mu2>
              </ode>
            </friction>
          </surface>
      </collision>

      <collision name='RB2_col5'>
        <pose>0.35 0 0.0245 0 0 0</pose>
        <geometry>
        <cylinder>
            <length>0.011 </length>
            <radius>0.027</radius>
          </cylinder>
        </geometry>
	<surface>
            <friction>
              <ode>
                <mu>100.000000</mu>
                <mu2>100.000000</mu2>
              </ode>
            </friction>
          </surface>
      </collision>

      <collision name='RB2_col6'>
        <pose>0.35 0 -0.0245 0 0 0</pose>
        <geometry>
        <cylinder>
            <length>0.011 </length>
            <radius>0.027</radius>
          </cylinder>
        </geometry>
	<surface>
            <friction>
              <ode>
                <mu>100.000000</mu>
                <mu2>100.000000</mu2>
              </ode>
            </friction>
          </surface>
      </collision>
</link>

<link name='RB_3'> <!-- back right leg lower -->
      <pose>-0.3374 -0.2535 -0.35 1.57079632679 1.57079632679 0</pose>
      <inertial>
        <mass>0.5761362</mass>
        <pose>0.12407 0.019161 0 0 0 0</pose>
        <inertia>
          <ixx>0.0005064730114</ixx>
          <ixy>0.0011799485469</ixy>
          <ixz>0</ixz>
          <iyy>0.0112618365401</iyy>
          <iyz>0</iyz>
          <izz>0.0115659868838</izz>
        </inertia>
      </inertial>

      <visual name="RB3_vis1">
        <pose>0 0 0 0 0 0</pose>
        <material>
          <ambient>0.196078431372549 0.196078431372549 0.196078431372549 1</ambient>
          <diffuse>0.196078431372549 0.196078431372549 0.196078431372549 1</diffuse>
        </material>
        <geometry>
          <mesh>
            <scale>1 1 1</scale>
            <uri>model://aidin8/meshes/meshes_surface/Leg_Knee_stp.STL</uri>
          </mesh>
        </geometry>
      </visual>

      <collision name='RB3_col1'>
        <pose>0 0 0 0 0 0</pose>
        <geometry>
        <cylinder>
            <length>0.03</length>
            <radius>0.02</radius>
          </cylinder>
        </geometry>
	<surface>
            <friction>
              <ode>
                <mu>100.000000</mu>
                <mu2>100.000000</mu2>
              </ode>
            </friction>
          </surface>
      </collision>
<!--
      <collision name='RB3_col2'>
        <pose>0.0152 -0.0025 0 0 0 0</pose>
        <geometry>
    	  <box>
              <size>0.03 0.045 0.036</size>
          </box>
        </geometry>
	<surface>
            <friction>
              <ode>
                <mu>100.000000</mu>
                <mu2>100.000000</mu2>
              </ode>
            </friction>
          </surface>
      </collision>
-->
      <collision name='RB3_col3'>
        <pose>0.1007581 0.0255584 0 0 0 0.41887902048</pose>
        <geometry>
    	  <box>
              <size>0.17 0.035 0.036</size>
          </box>
        </geometry>
	<surface>
            <friction>
              <ode>
                <mu>100.000000</mu>
                <mu2>100.000000</mu2>
              </ode>
            </friction>
          </surface>
      </collision>

      <collision name='RB3_col4'>
        <pose>0.2109143 0.0609071 0 0 0 0.05925392811</pose>
        <geometry>
    	  <box>
              <size>0.0771692 0.035 0.036</size>
          </box>
        </geometry>
	<surface>
            <friction>
              <ode>
                <mu>100.000000</mu>
                <mu2>100.000000</mu2>
              </ode>
            </friction>
          </surface>
      </collision>
            
      <collision name='RB3_col5'>
        <pose>0.3223493 0.0351797 0 0 0 -0.34906585040</pose>
        <geometry>
    	  <box>
              <size>0.17 0.035 0.036</size>
          </box>
        </geometry>
	      <surface>
            <friction>
              <ode>
                <mu>100.000000</mu>
                <mu2>100.000000</mu2>
              </ode>
            </friction>
          </surface>
      </collision>

<!--back right foot sphere-->
      <!--collision name='RB3_col6'>
      <max_contacts>10</max_contacts>
        <pose>0.4 0 0 0 0 0</pose>
        <geometry>
    	  <sphere>
              <radius>0.024</radius>
          </sphere>
        </geometry>
	      <surface>
            <friction>
              <ode>
                <mu>1000.000000</mu>
                <mu2>1000.000000</mu2>
              </ode>
            </friction>
          </surface>
      </collision-->

<!--back right foot cylinder-->
      <collision name='RB3_col7'>
      <max_contacts>10</max_contacts>
        <pose>0.4 0 0 0 0 0</pose>
        <geometry>
        <cylinder>
            <length>0.036</length>
            <radius>0.024</radius>
          </cylinder>
        </geometry>
	      <surface>
            <friction>
              <ode>
                <mu>1000.000000</mu>
                <mu2>1000.000000</mu2>
              </ode>
            </friction>
          </surface>
      </collision>

    <sensor name="RB_3_sensor" type="contact">
      <plugin name="RB_plugin" filename="libcontact.so"/>
      <always_on>true</always_on>
      <update_rate>250</update_rate>
      <contact>
        <collision>RB3_col6</collision>
      </contact>
    </sensor>
</link>

<link name='RB_link1'>
      <pose>-0.3374 -0.2535 0 1.57079632679 -1.74532925199 0</pose> <!-- 10도 -->
      <inertial>
        <mass>0.3184983</mass>
        <pose>0.008126 -0.0005283 -0.0305419 0 0 0</pose>
        <inertia>
          <ixx>0.0007804785859</ixx>
          <ixy>0.00000226856</ixy>
          <ixz>0.0000785325361</ixz>
          <iyy>0.0008456468004</iyy>
          <iyz>-0.0000052002314</iyz>
          <izz>0.0001116486791</izz>
        </inertia>
      </inertial>
      <visual name="RB_link1_vis1">
        <pose>0 0 0 0 0 0</pose>
        <material>
          <ambient>0.196078431372549 0.196078431372549 0.196078431372549 1</ambient>
          <diffuse>0.196078431372549 0.196078431372549 0.196078431372549 1</diffuse>
        </material>
        <geometry>
          <mesh>
            <scale>1 1 1</scale>
            <uri>model://aidin8/meshes/meshes_surface/Knee_link1_right_stp.STL</uri>
          </mesh>
        </geometry>
      </visual>
</link>

<link name='RB_link2'>
      <pose>-0.3434777 -0.2535 +0.0344683 1.57079632679 1.57079632679 0</pose>
      <inertial>
        <mass>0.20931</mass>
        <pose>0.175 0 0 0 0 0</pose>
        <inertia>
          <ixx>0.00000747991</ixx>
          <ixy>0</ixy>
          <ixz>0</ixz>
          <iyy>0.00238918720</iyy>
          <iyz>0</iyz>
          <izz>0.00239407889</izz>
        </inertia>
      </inertial>
      <visual name="RB_link2_vis1">
        <pose>0 0 0 0 0 0</pose>
        <material>
          <ambient>0.752941176470588 0.752941176470588 0.752941176470588 1</ambient>
          <diffuse>0.752941176470588 0.752941176470588 0.752941176470588 1</diffuse>
        </material>
        <geometry>
          <mesh>
            <scale>1 1 1</scale>
            <uri>model://aidin8/meshes/meshes_surface/Knee_link2_stp.STL</uri>
          </mesh>
        </geometry>
      </visual>
</link>

  <link name='LB_1'> <!-- back left shoulder -->
     <pose>-0.3374 +0.119 0 1.57079632679 0 1.57079632679</pose>
      <inertial>
        <mass>6.0096951</mass>
        <pose>0.002369 0.0000223 0.0358104 0 0 0</pose>
        <inertia>
          <ixx>0.0255491010927</ixx>
          <ixy>-0.0000047311699</ixy>
          <ixz>-0.0009887851002</ixz>
          <iyy>0.0359194975543</iyy>
          <iyz>0.000008004696</iyz>
          <izz>0.0169033455935</izz>
        </inertia>
      </inertial>

     <visual name="LB_vis11">
        <pose>0 0 0 0 0 0</pose>
        <material>
          <ambient>0.752941176470588 0.752941176470588 0.752941176470588 1</ambient>
          <diffuse>0.752941176470588 0.752941176470588 0.752941176470588 1</diffuse>
        </material>
        <geometry>
          <mesh>
            <scale>1 1 1</scale>
            <uri>model://aidin8/meshes/meshes_surface/Leg_Scapular_LR_stp_v2.STL</uri>
          </mesh>
        </geometry>
      </visual>

      <collision name='LB_col1'>
        <pose>0 0 0.0507 0 0 0</pose>
        <geometry>
        <cylinder>
            <length>0.2334</length>
            <radius>0.0535</radius>
          </cylinder>
        </geometry>
	<surface>
            <friction>
              <ode>
                <mu>100.000000</mu>
                <mu2>100.000000</mu2>
              </ode>
            </friction>
          </surface>
      </collision>

      <collision name='LB_col2'>
        <pose>0.0083 0 0 0 1.57079632679 0</pose>
        <geometry>
        <cylinder>
            <length>0.1984</length>
            <radius>0.0535</radius>
          </cylinder>
        </geometry>
	<surface>
            <friction>
              <ode>
                <mu>100.000000</mu>
                <mu2>100.000000</mu2>
              </ode>
            </friction>
          </surface>
      </collision>
</link>

<link name='LB_2'> <!-- back left leg upper -->
      <pose>-0.3374 +0.2535 0 1.57079632679 1.57079632679 0</pose>
      <inertial>
        <mass>0.8320777</mass>
        <pose>0.1763086 -0.0152343 -0.0002264 0 0 0</pose>
        <inertia>
          <ixx>0.0007072507423</ixx>
          <ixy>0.0000163954475</ixy>
          <ixz>0.0000331849652</ixz>
          <iyy>0.015000924209</iyy>
          <iyz>-0.0000028381293</iyz>
          <izz>0.0149901916315</izz>
        </inertia>
      </inertial>

      <visual name="LB2_vis11">
        <pose>0 0 0 0 0 0</pose>
        <material>
          <ambient>1 0 0 1</ambient>
          <diffuse>1 0 0 1</diffuse>
        </material>
        <geometry>
          <mesh>
            <scale>1 1 1</scale>
            <uri>model://aidin8/meshes/meshes_surface/Leg_Hip_left_stp.STL</uri>
          </mesh>
        </geometry>
      </visual>

      <collision name='LB2_col1'>
        <pose>0 0 0 0 0 0</pose>
        <geometry>
        <cylinder>
            <length>0.054</length>
            <radius>0.027</radius>
          </cylinder>
        </geometry>
	<surface>
            <friction>
              <ode>
                <mu>100.000000</mu>
                <mu2>100.000000</mu2>
              </ode>
            </friction>
          </surface>
      </collision>

      <collision name='LB2_col2'>
        <pose>0.055 -0.021 0 0 0 0</pose>
        <geometry>
    	  <box>
              <size>0.06 0.06 0.054</size>
          </box>
        </geometry>
	<surface>
            <friction>
              <ode>
                <mu>100.000000</mu>
                <mu2>100.000000</mu2>
              </ode>
            </friction>
          </surface>
      </collision>

      <collision name='LB2_col3'>
        <pose>0.175 -0.021 0 0 1.57079632679 0</pose>
        <geometry>
        <cylinder>
            <length>0.18</length>
            <radius>0.025</radius>
          </cylinder>
        </geometry>
	<surface>
            <friction>
              <ode>
                <mu>100.000000</mu>
                <mu2>100.000000</mu2>
              </ode>
            </friction>
          </surface>
      </collision>

      <collision name='LB2_col4'>
         <pose>0.295 -0.021 0 0 0 0</pose>
        <geometry>
    	  <box>
              <size>0.06 0.06 0.054</size>
          </box>
        </geometry>
	<surface>
            <friction>
              <ode>
                <mu>100.000000</mu>
                <mu2>100.000000</mu2>
              </ode>
            </friction>
          </surface>
      </collision>

      <collision name='LB2_col5'>
        <pose>0.35 0 0.0245 0 0 0</pose>
        <geometry>
        <cylinder>
            <length>0.011 </length>
            <radius>0.027</radius>
          </cylinder>
        </geometry>
	<surface>
            <friction>
              <ode>
                <mu>100.000000</mu>
                <mu2>100.000000</mu2>
              </ode>
            </friction>
          </surface>
      </collision>

      <collision name='LB2_col6'>
        <pose>0.35 0 -0.0245 0 0 0</pose>
        <geometry>
        <cylinder>
            <length>0.011 </length>
            <radius>0.027</radius>
          </cylinder>
        </geometry>
	<surface>
            <friction>
              <ode>
                <mu>100.000000</mu>
                <mu2>100.000000</mu2>
              </ode>
            </friction>
          </surface>
      </collision>
</link>

<link name='LB_3'> <!-- back left leg lower -->
      <pose>-0.3374 +0.2535 -0.35 1.57079632679 1.57079632679 0</pose>
      <inertial>
        <mass>0.5761362</mass>
        <pose>0.12407 0.019161 0 0 0 0</pose>
        <inertia>
          <ixx>0.0005064730114</ixx>
          <ixy>0.0011799485469</ixy>
          <ixz>0</ixz>
          <iyy>0.0112618365401</iyy>
          <iyz>0</iyz>
          <izz>0.0115659868838</izz>
        </inertia>
      </inertial>

      <visual name="L9_visual">
        <pose>0 0 0 0 0 0</pose>
        <material>
          <ambient>0.196078431372549 0.196078431372549 0.196078431372549 1</ambient>
          <diffuse>0.196078431372549 0.196078431372549 0.196078431372549 1</diffuse>
        </material>
        <geometry>
          <mesh>
            <scale>1 1 1</scale>
            <uri>model://aidin8/meshes/meshes_surface/Leg_Knee_stp.STL</uri>
          </mesh>
        </geometry>
      </visual>

      <collision name='LB3_col1'>
        <pose>0 0 0 0 0 0</pose>
        <geometry>
        <cylinder>
            <length>0.03</length>
            <radius>0.02</radius>
          </cylinder>
        </geometry>
	<surface>
            <friction>
              <ode>
                <mu>100.000000</mu>
                <mu2>100.000000</mu2>
              </ode>
            </friction>
          </surface>
      </collision>
<!--
      <collision name='LB3_col2'>
        <pose>0.0152 -0.0025 0 0 0 0</pose>
        <geometry>
    	  <box>
              <size>0.03 0.045 0.036</size>
          </box>
        </geometry>
	<surface>
            <friction>
              <ode>
                <mu>100.000000</mu>
                <mu2>100.000000</mu2>
              </ode>
            </friction>
          </surface>
      </collision>
-->
      <collision name='LB3_col3'>
        <pose>0.1007581 0.0255584 0 0 0 0.41887902048</pose>
        <geometry>
    	  <box>
              <size>0.17 0.035 0.036</size>
          </box>
        </geometry>
	<surface>
            <friction>
              <ode>
                <mu>100.000000</mu>
                <mu2>100.000000</mu2>
              </ode>
            </friction>
          </surface>
      </collision>

      <collision name='LB3_col4'>
        <pose>0.2109143 0.0609071 0 0 0 0.05925392811</pose>
        <geometry>
    	  <box>
              <size>0.0771692 0.035 0.036</size>
          </box>
        </geometry>
	<surface>
            <friction>
              <ode>
                <mu>100.000000</mu>
                <mu2>100.000000</mu2>
              </ode>
            </friction>
          </surface>
      </collision>
            
      <collision name='LB3_col5'>
        <pose>0.3223493 0.0351797 0 0 0 -0.34906585040</pose>
        <geometry>
    	  <box>
              <size>0.17 0.035 0.036</size>
          </box>
        </geometry>
	      <surface>
            <friction>
              <ode>
                <mu>100.000000</mu>
                <mu2>100.000000</mu2>
              </ode>
            </friction>
          </surface>
      </collision>

<!--back left foot sphere-->
      <!--collision name='LB3_col6'> 
      <max_contacts>10</max_contacts>
        <pose>0.4 0 0 0 0 0</pose>
        <geometry>
    	  <sphere>
              <radius>0.024</radius>
          </sphere>
        </geometry>
	      <surface>
            <friction>
              <ode>
                <mu>1000.000000</mu>
                <mu2>1000.000000</mu2>
              </ode>
            </friction>
          </surface>
      </collision-->

<!--back left foot cylinder-->
      <collision name='LB3_col7'>
      <max_contacts>10</max_contacts>
        <pose>0.4 0 0 0 0 0</pose>
        <geometry>
        <cylinder>
            <length>0.036</length>
            <radius>0.024</radius>
          </cylinder>
        </geometry>
	      <surface>
            <friction>
              <ode>
                <mu>1000.000000</mu>
                <mu2>1000.000000</mu2>
              </ode>
            </friction>
          </surface>
      </collision>

    <sensor name="LB_3_sensor" type="contact">
      <plugin name="LB_plugin" filename="libcontact.so"/>
      <always_on>true</always_on>
      <update_rate>250</update_rate>
      <contact>
        <collision>LB3_col6</collision>
      </contact>
    </sensor>
      </link>

<link name='LB_link1'>
      <pose>-0.3374 +0.2535 0 1.57079632679 -1.74532925199 0</pose> <!-- 10도 -->
      <inertial>
        <mass>0.3184983</mass>
        <pose>0.008126 -0.0005283 0.0305419 0 0 0</pose>
        <inertia>
          <ixx>0.0007804785859</ixx>
          <ixy>0.00000226856</ixy>
          <ixz>-0.0000785325361</ixz>
          <iyy>0.0008456468004</iyy>
          <iyz>0.0000052002314</iyz>
          <izz>0.0001116486791</izz>
        </inertia>
      </inertial>

      <visual name="LB_link1_vis1">
        <pose>0 0 0 0 0 0</pose>
        <material>
          <ambient>0.196078431372549 0.196078431372549 0.196078431372549 1</ambient>
          <diffuse>0.196078431372549 0.196078431372549 0.196078431372549 1</diffuse>
        </material>
        <geometry>
          <mesh>
            <scale>1 1 1</scale>
            <uri>model://aidin8/meshes/meshes_surface/Knee_link1_left_stp.STL</uri>
          </mesh>
        </geometry>
      </visual>
</link>

<link name='LB_link2'>
      <pose>-0.3434777 +0.2535 +0.0344683 1.57079632679 1.57079632679 0</pose>
      <inertial>
        <mass>0.20931</mass>
        <pose>0.175 0 0 0 0 0</pose>
        <inertia>
          <ixx>0.00000747991</ixx>
          <ixy>0</ixy>
          <ixz>0</ixz>
          <iyy>0.00238918720</iyy>
          <iyz>0</iyz>
          <izz>0.00239407889</izz>
        </inertia>
      </inertial>
      <visual name="LB_link2_vis1">
        <pose>0 0 0 0 0 0</pose>
        <material>
          <ambient>0.752941176470588 0.752941176470588 0.752941176470588 1</ambient>
          <diffuse>0.752941176470588 0.752941176470588 0.752941176470588 1</diffuse>
        </material>
        <geometry>
          <mesh>
            <scale>1 1 1</scale>
            <uri>model://aidin8/meshes/meshes_surface/Knee_link2_stp.STL</uri>
          </mesh>
        </geometry>
      </visual>
</link>

<!-- //////////////////////////////joint/////////////////////////////// -->

<joint name='RFJ1' type='revolute'>
      <child>RF_1</child>
      <parent>body</parent>
 <pose>0 0 0 0 0 0</pose>
      <axis>
        <xyz>0 0 1</xyz>
        <limit>
          <lower>-3</lower>
          <upper>3</upper>
        </limit>
        <dynamics>
          <damping>1.5</damping>
        </dynamics>
      </axis>
	<sensor name="RFJ1_sensor" type="force_torque">
          <update_rate>100</update_rate>
        </sensor>
    </joint>

<joint name='RFJ2' type='revolute'>
      <child>RF_2</child>
      <parent>RF_1</parent>
 <pose>0 0 0 0 0 0</pose>
      <axis>
        <xyz>0 0 1</xyz>
        <limit>
          <lower>-3</lower>
          <upper>3</upper>
        </limit>
        <dynamics>
          <damping>1.5</damping>
        </dynamics>
      </axis>
	<sensor name="RFJ2_sensor" type="force_torque">
          <update_rate>100</update_rate>
        </sensor>
    </joint>

<joint name='RFJ3' type='revolute'>
      <child>RF_link1</child>
      <parent>RF_1</parent>
 <pose>0 0 0 0 0 0</pose>
      <axis>
        <xyz>0 0 1</xyz>
        <limit>
          <lower>-3</lower>
          <upper>3</upper>
        </limit>
        <dynamics>
          <damping>1.5</damping>
        </dynamics>
      </axis>
	<sensor name="RFJ3_sensor" type="force_torque">
          <update_rate>100</update_rate>
        </sensor>
    </joint>


<joint name='RFJ_link1' type='revolute'>
      <child>RF_3</child>
      <parent>RF_2</parent>
 <pose>0 0 0 0 0 0</pose>
      <axis>
        <xyz>0 0 1</xyz>
        <limit>
          <lower>-3</lower>
          <upper>3</upper>
        </limit>
        <dynamics>
          <damping>1.5</damping>
        </dynamics>
      </axis>
    </joint>

<joint name='RFJ_link2' type='revolute'>
      <child>RF_link2</child>
      <parent>RF_link1</parent>
 <pose>0 0 0 0 0 0</pose>
      <axis>
        <xyz>0 0 1</xyz>
        <limit>
          <lower>-3</lower>
          <upper>3</upper>
        </limit>
        <dynamics>
          <damping>1.5</damping>
        </dynamics>
      </axis>
    </joint>

<joint name='RFJ_link3' type='revolute'>
      <child>RF_link2</child>
      <parent>RF_3</parent>
 <pose>0.35 0 0 0 0 0</pose>
      <axis>
        <xyz>0 0 1</xyz>
        <limit>
          <lower>-3</lower>
          <upper>3</upper>
        </limit>
        <dynamics>
          <damping>1.5</damping>
        </dynamics>
      </axis>
    </joint>

<!--////////////////////////////////////////////// LF joint //////////////////////////////////////////////////-->

<joint name='LFJ1' type='revolute'>
      <child>LF_1</child>
      <parent>body</parent>
      <pose>0 0 0 0 0 0</pose>
      <axis>
        <xyz>0 0 1</xyz>
        <limit>
          <lower>-3</lower>
          <upper>3</upper>
        </limit>
        <dynamics>
          <damping>1.5</damping>
        </dynamics>
      </axis>
	<sensor name="LFJ1_sensor" type="force_torque">
          <update_rate>100</update_rate>
        </sensor>
    </joint>

<joint name='LFJ2' type='revolute'>
      <child>LF_2</child>
      <parent>LF_1</parent>
 <pose>0 0 0 0 0 0</pose>
      <axis>
        <xyz>0 0 1</xyz>
        <limit>
          <lower>-3</lower>
          <upper>3</upper>
        </limit>
        <dynamics>
          <damping>1.5</damping>
        </dynamics>
      </axis>
	<sensor name="LFJ2_sensor" type="force_torque">
          <update_rate>100</update_rate>
        </sensor>
    </joint>

<joint name='LFJ3' type='revolute'>
      <child>LF_link1</child>
      <parent>LF_1</parent>
 <pose>0 0 0 0 0 0</pose>
      <axis>
        <xyz>0 0 1</xyz>
        <limit>
          <lower>-3</lower>
          <upper>3</upper>
        </limit>
        <dynamics>
          <damping>1.5</damping>
        </dynamics>
      </axis>
	<sensor name="LFJ3_sensor" type="force_torque">
          <update_rate>100</update_rate>
        </sensor>
    </joint>

<joint name='LFJ_link1' type='revolute'>
      <child>LF_3</child>
      <parent>LF_2</parent>
 <pose>0 0 0 0 0 0</pose>
      <axis>
        <xyz>0 0 1</xyz>
        <limit>
          <lower>-3</lower>
          <upper>3</upper>
        </limit>
        <dynamics>
          <damping>1.5</damping>
        </dynamics>
      </axis>
    </joint>

<joint name='LFJ_link2' type='revolute'>
      <child>LF_link2</child>
      <parent>LF_link1</parent>
 <pose>0 0 0 0 0 0</pose>
      <axis>
        <xyz>0 0 1</xyz>
        <limit>
          <lower>-3</lower>
          <upper>3</upper>
        </limit>
        <dynamics>
          <damping>1.5</damping>
        </dynamics>
      </axis>
    </joint>

<joint name='LFJ_link3' type='revolute'>
      <child>LF_link2</child>
      <parent>LF_3</parent>
 <pose>0.35 0 0 0 0 0</pose>
      <axis>
        <xyz>0 0 1</xyz>
        <limit>
          <lower>-3</lower>
          <upper>0</upper>
        </limit>
        <dynamics>
          <damping>1.5</damping>
        </dynamics>
      </axis>
    </joint>

<!--////////////////////////////////////////////// LB joint //////////////////////////////////////////////////-->

<joint name='LBJ1' type='revolute'>
      <child>LB_1</child>
      <parent>body</parent>
 <pose>0 0 0 0 0 0</pose>
      <axis>
        <xyz>0 0 1</xyz>
        <limit>
          <lower>-3</lower>
          <upper>3</upper>
        </limit>
        <dynamics>
          <damping>1.5</damping>
        </dynamics>
      </axis>
	<sensor name="LBJ1_sensor" type="force_torque">
          <update_rate>100</update_rate>
        </sensor>
    </joint>

<joint name='LBJ2' type='revolute'>
      <child>LB_2</child>
      <parent>LB_1</parent>
 <pose>0 0 0 0 0 0</pose>
      <axis>
        <xyz>0 0 1</xyz>
        <limit>
          <lower>-3</lower>
          <upper>3</upper>
        </limit>
        <dynamics>
          <damping>1.5</damping>
        </dynamics>
      </axis>
	<sensor name="LBJ2_sensor" type="force_torque">
          <update_rate>100</update_rate>
        </sensor>
    </joint>

<joint name='LBJ3' type='revolute'>
      <child>LB_link1</child>
      <parent>LB_1</parent>
 <pose>0 0 0 0 0 0</pose>
      <axis>
        <xyz>0 0 1</xyz>
        <limit>
          <lower>-3</lower>
          <upper>3</upper>
        </limit>
        <dynamics>
          <damping>1.5</damping>
        </dynamics>
      </axis>
	<sensor name="LBJ3_sensor" type="force_torque">
          <update_rate>100</update_rate>
        </sensor>
    </joint>

<joint name='LBJ_link1' type='revolute'>
      <child>LB_3</child>
      <parent>LB_2</parent>
 <pose>0 0 0 0 0 0</pose>
      <axis>
        <xyz>0 0 1</xyz>
        <limit>
          <lower>-3</lower>
          <upper>3</upper>
        </limit>
        <dynamics>
          <damping>1.5</damping>
        </dynamics>
      </axis>
    </joint>

<joint name='LBJ_link2' type='revolute'>
      <child>LB_link2</child>
      <parent>LB_link1</parent>
 <pose>0 0 0 0 0 0</pose>
      <axis>
        <xyz>0 0 1</xyz>
        <limit>
          <lower>-3</lower>
          <upper>3</upper>
        </limit>
        <dynamics>
          <damping>1.5</damping>
        </dynamics>
      </axis>
    </joint>

<joint name='LBJ_link3' type='revolute'>
      <child>LB_link2</child>
      <parent>LB_3</parent>
 <pose>0.35 0 0 0 0 0</pose>
      <axis>
        <xyz>0 0 1</xyz>
        <limit>
          <lower>-3</lower>
          <upper>0</upper>
        </limit>
        <dynamics>
          <damping>1.5</damping>
        </dynamics>
      </axis>
    </joint>

<joint name='RBJ1' type='revolute'>
      <child>RB_1</child>
      <parent>body</parent>
 <pose>0 0 0 0 0 0</pose>
      <axis>
        <xyz>0 0 1</xyz>
        <limit>
          <lower>-3</lower>
          <upper>3</upper>
        </limit>
        <dynamics>
          <damping>1.5</damping>
        </dynamics>
      </axis>
	<sensor name="RBJ1_sensor" type="force_torque">
          <update_rate>100</update_rate>
        </sensor>
    </joint>

<joint name='RBJ2' type='revolute'>
      <child>RB_2</child>
      <parent>RB_1</parent>
 <pose>0 0 0 0 0 0</pose>
      <axis>
        <xyz>0 0 1</xyz>
        <limit>
          <lower>-3</lower>
          <upper>3</upper>
        </limit>
        <dynamics>
          <damping>1.5</damping>
        </dynamics>
      </axis>
	<sensor name="RBJ2_sensor" type="force_torque">
          <update_rate>100</update_rate>
        </sensor>
    </joint>

<joint name='RBJ3' type='revolute'>
      <child>RB_link1</child>
      <parent>RB_1</parent>
 <pose>0 0 0 0 0 0</pose>
      <axis>
        <xyz>0 0 1</xyz>
        <limit>
          <lower>-3</lower>
          <upper>3</upper>
        </limit>
        <dynamics>
          <damping>1.5</damping>
        </dynamics>
      </axis>
	<sensor name="RBJ3_sensor" type="force_torque">
          <update_rate>100</update_rate>
        </sensor>
    </joint>


<joint name='RBJ_link1' type='revolute'>
      <child>RB_3</child>
      <parent>RB_2</parent>
 <pose>0 0 0 0 0 0</pose>
      <axis>
        <xyz>0 0 1</xyz>
        <limit>
          <lower>-3</lower>
          <upper>3</upper>
        </limit>
        <dynamics>
          <damping>1.5</damping>
        </dynamics>
      </axis>
    </joint>

<joint name='RBJ_link2' type='revolute'>
      <child>RB_link2</child>
      <parent>RB_link1</parent>
 <pose>0 0 0 0 0 0</pose>
      <axis>
        <xyz>0 0 1</xyz>
        <limit>
          <lower>-3</lower>
          <upper>3</upper>
        </limit>
        <dynamics>
          <damping>1.5</damping>
        </dynamics>
      </axis>
    </joint>

<joint name='RBJ_link3' type='revolute'>
      <child>RB_link2</child>
      <parent>RB_3</parent>
 <pose>0.35 0 0 0 0 0</pose>
      <axis>
        <xyz>0 0 1</xyz>
        <limit>
          <lower>-3</lower>
          <upper>0</upper>
        </limit>
        <dynamics>
          <damping>1.5</damping>
        </dynamics>
      </axis>
    </joint>

<!--
    <link name="neck">
      <gravity>0</gravity>
      <pose>0 0.485 0.02 0 0 0</pose>
      <collision name="neck_col">
        <pose>0 0 0 0 0 0</pose>
        <geometry>
          <box>
            <size>0.01 0.01 0.01</size>
          </box>
        </geometry>
        <surface>
          <contact>
            <collide_bitmask>1</collide_bitmask>
          </contact>
        </surface>
      </collision>
      <visual name="neck_visual">
        <pose>0 -0.05 0 0 0 0</pose>
        <geometry>
          <box>
            <size>0.03 0.1 0.03</size>
          </box>
        </geometry>
        <material>
          <ambient>0.1 0.1 0.1 1</ambient>
          <diffuse>0.1 0.1 0.2 1</diffuse>
          <specular>0 0 0 0</specular>
          <emissive>0 0 0 1</emissive>
        </material>
      </visual>
    </link>
    <joint name="neck_joint" type="fixed">
      <axis>
        <xyz>0 0 0</xyz>
      </axis>
      <pose>0 0 0 0 0 0</pose>
      <parent>body</parent>
      <child>neck</child>
    </joint> 
-->
<!-- ////////////////////////Cameras//////////////////////// -->

<plugin name="ROSaidin8Plugin_multi" filename="libsub_aidin8_multi.so">
 <!-- <Namespace>aidinvi</Namespace> -->
</plugin>

</model>
</sdf>
<!--camera1 <pose> 0.0  0.535 -0.013        0           0.5235987756  1.570796327 </pose> 
    camera2 <pose> 0.0 -0.090 -0.107046994 -1.570796327 1.570796327   0           </pose>
    camera3 <pose> 0.0 -0.535 -0.013        0           0.5235987756 -1.570796327 </pose> 
    camera5 <pose> 0.0  0.535 -0.013        0           1.0471975512  1.570796327 </pose>  -->
